Workbook

Sheet SUMMARY
A1: Republic of the Philippines
A2: COMMISSION ON ELECTIONS
A3: Records and Statistics Division, ERSD
A5: NUMBER AND TURN-OUT OF REGISTERED VOTERS AND VOTERS WHO ACTUALLY VOTED
A6: May 12, 2025 National and Local Elections
A7: GROUP | D7: NUMBER OF CLUSTERED PRECINCTS | E7: NUMBER OF REGISTERED VOTERS | F7: NUMBER OF VOTERS WHO ACTUALLY VOTED | G7: VOTER'S TURN-OUT
A8: Local AES | D8: 93287 | E8: 68431965 | F8: 57070411 | G8: =SUM(F8/E8) -> 0.833973
A9: Overseas Voting | E9: 1241688 | F9: 228490 | G9: =SUM(F9/E9) -> 0.18401563
A10: Local Absentee Voting | F10: 52067
A11: GRAND TOTAL | E11: =SUM(E8:E10) -> 69673653 | F11: =SUM(F8:F10) -> 57350968 | G11: =SUM(F11/E11) -> 0.82313709
A13: NOTE:
A14: The Registered Voters of LAV is included in LOCAL AES

Sheet regional_summary
A1: Republic of the Philippines
A2: COMMISSION ON ELECTIONS
A3: Records and Statistics Division, ERSD
A5: NUMBER AND TURN-OUT OF REGISTERED VOTERS AND VOTERS WHO ACTUALLY VOTED BY REGION
A6: May 12, 2025 National and Local Elections
A9: As of August 2025
A10: REGION | C10: NUMBER OF CLUSTERED PRECINCTS | D10: NUMBER OF REGISTERED VOTERS | E10: NUMBER OF VOTERS WHO ACTUALLY VOTED | F10: VOTER'S TURN-OUT
A14: P H I L I P P I N E S | C14: =SUM(C15:C32) -> 93287 | D14: =SUM(D15:D32) -> 68431965 | E14: =SUM(E15:E32) -> 57070411 | F14: =SUM(E14/D14) -> 0.833973
A15: N. C. R. | C15: =provl_summary!C15 -> 9030 | D15: =provl_summary!D15 -> 7563520 | E15: =provl_summary!E15 -> 6040069 | F15: =SUM(E15/D15) -> 0.7985791
A16: CORDILLERA ADM. REGION | C16: =provl_summary!C16 -> 1963 | D16: =provl_summary!D16 -> 1105063 | E16: =provl_summary!E16 -> 946327 | F16: =SUM(E16/D16) -> 0.8563557
A17: REGION I | C17: =provl_summary!C23 -> 5337 | D17: =provl_summary!D23 -> 3633900 | E17: =provl_summary!E23 -> 3178310 | F17: =SUM(E17/D17) -> 0.87462781
A18: REGION II | C18: =provl_summary!C28 -> 3559 | D18: =provl_summary!D28 -> 2358587 | E18: =provl_summary!E28 -> 2000940 | F18: =SUM(E18/D18) -> 0.84836387
A19: REGION III | C19: =provl_summary!C34:C34 -> 9584 | D19: =provl_summary!D34:D34 -> 7699404 | E19: =provl_summary!E34:E34 -> 6527627 | F19: =SUM(E19/D19) -> 0.84780939
A20: REGION IV-A | C20: =provl_summary!C42 -> 12346 | D20: =provl_summary!D42 -> 9714079 | E20: =provl_summary!E42 -> 7849709 | F20: =SUM(E20/D20) -> 0.80807547
A21: REGION IV-B | C21: =provl_summary!C48 -> 2951 | D21: =provl_summary!D48 -> 2055827 | E21: =provl_summary!E48 -> 1704649 | F21: =SUM(E21/D21) -> 0.82917921
A22: REGION V | C22: =provl_summary!C54 -> 5877 | D22: =provl_summary!D54 -> 4053977 | E22: =provl_summary!E54 -> 3450811 | F22: =SUM(E22/D22) -> 0.85121623
A23: REGION VI | C23: =provl_summary!C61 -> 4971 | D23: =provl_summary!D61 -> 3128562 | E23: =provl_summary!E61 -> 2686216 | F23: =SUM(E23/D23) -> 0.85861044
A24: NEGROS ISLAND REGION (NIR) | C24: =provl_summary!C67 -> 3922 | D24: =provl_summary!D67 -> 3059321 | E24: =provl_summary!E67 -> 2585766 | F24: =SUM(E24/D24) -> 0.84520912
A25: REGION VII | C25: =provl_summary!C71 -> 5662 | D25: =provl_summary!D71 -> 4389344 | E25: =provl_summary!E71 -> 3797086 | F25: =SUM(E25/D25) -> 0.86506913
A26: REGION VIII | C26: =provl_summary!C74 -> 5670 | D26: =provl_summary!D74 -> 3259554 | E26: =provl_summary!E74 -> 2747755 | F26: =SUM(E26/D26) -> 0.84298496
A27: REGION IX | C27: =provl_summary!C81 -> 4048 | D27: =provl_summary!D81 -> 2869368 | E27: =provl_summary!E81 -> 2384181 | F27: =SUM(E27/D27) -> 0.83090806
A28: REGION X | C28: =provl_summary!C86 -> 4444 | D28: =provl_summary!D86 -> 3179252 | E28: =provl_summary!E86 -> 2731299 | F28: =SUM(E28/D28) -> 0.85910113
A29: REGION XI | C29: =provl_summary!C92 -> 4189 | D29: =provl_summary!D92 -> 3376470 | E29: =provl_summary!E92 -> 2779125 | F29: =SUM(E29/D29) -> 0.82308594
A30: REGION XII | C30: =provl_summary!C98 -> 3492 | D30: =provl_summary!D98 -> 2701992 | E30: =provl_summary!E98 -> 2200890 | F30: =SUM(E30/D30) -> 0.81454349
A31: CARAGA | C31: =provl_summary!C103 -> 2666 | D31: =provl_summary!D103 -> 1904917 | E31: =provl_summary!E103 -> 1613102 | F31: =SUM(E31/D31) -> 0.8468096
A32: B.A.R.M.M. | C32: =provl_summary!C109 -> 3576 | D32: =provl_summary!D109 -> 2378828 | E32: =provl_summary!E109 -> 1846549 | F32: =SUM(E32/D32) -> 0.77624318

Sheet provl_summary
A1: Republic of the Philippines
A2: COMMISSION ON ELECTIONS
A3: Records and Statistics Division, ERSD
A5: NUMBER AND TURN-OUT OF REGISTERED VOTERS AND VOTERS WHO ACTUALLY VOTED BY PROVINCE
A6: May 12, 2025 National and Local Elections
A9: As of August 2025
A10: REGION/PROVINCE | C10: NUMBER OF CLUSTERED PRECINCTS | D10: NUMBER OF REGISTERED VOTERS | E10: NUMBER OF VOTERS WHO ACTUALLY VOTED | F10: VOTER'S TURN-OUT
A14: P H I L I P P I N E S | C14: =SUM(C15+C16+C23+C28+C34+C42+C48+C54+C61+C67+C71+C74+C81+C86+C92+C98+C103+C109) -> 93287 | D14: =SUM(D15+D16+D23+D28+D34+D42+D48+D54+D61+D67+D71+D74+D81+D86+D92+D98+D103+D109) -> 68431965 | E14: =SUM(E15+E16+E23+E28+E34+E42+E48+E54+E61+E67+E71+E74+E81+E86+E92+E98+E103+E109) -> 57070411 | F14: =SUM(E14/D14) -> 0.833973
A15: N. C. R. | C15: =SUM(mun_coc!C14) -> 9030 | D15: =SUM(mun_coc!D14) -> 7563520 | E15: =SUM(mun_coc!E14) -> 6040069 | F15: =SUM(E15/D15) -> 0.7985791
A16: CORDILLERA ADM. REGION | C16: =SUM(C17:C22) -> 1963 | D16: =SUM(D17:D22) -> 1105063 | E16: =SUM(E17:E22) -> 946327 | F16: =SUM(E16/D16) -> 0.8563557
B17: ABRA | C17: =SUM(mun_coc!C60) -> 364 | D17: =SUM(mun_coc!D60) -> 188957 | E17: =SUM(mun_coc!E60) -> 172959 | F17: =SUM(E17/D17) -> 0.91533524
B18: APAYAO | C18: =SUM(mun_coc!C91) -> 159 | D18: =SUM(mun_coc!D91) -> 83441 | E18: =SUM(mun_coc!E91) -> 72548 | F18: =SUM(E18/D18) -> 0.86945267
B19: BENGUET | C19: =SUM(mun_coc!C102) -> 676 | D19: =SUM(mun_coc!D102) -> 416145 | E19: =SUM(mun_coc!E102) -> 343068 | F19: =SUM(E19/D19) -> 0.82439534
B20: IFUGAO | C20: =SUM(mun_coc!C121) -> 258 | D20: =SUM(mun_coc!D121) -> 136318 | E20: =SUM(mun_coc!E121) -> 117835 | F20: =SUM(E20/D20) -> 0.86441262
B21: KALINGA | C21: =SUM(mun_coc!C136) -> 272 | D21: =SUM(mun_coc!D136) -> 158555 | E21: =SUM(mun_coc!E136) -> 140554 | F21: =SUM(E21/D21) -> 0.88646842
B22: MOUNTAIN PROVINCE | C22: =SUM(mun_coc!C148) -> 234 | D22: =SUM(mun_coc!D148) -> 121647 | E22: =SUM(mun_coc!E148) -> 99363 | F22: =SUM(E22/D22) -> 0.81681422
A23: REGION I | C23: =SUM(C24:C27) -> 5337 | D23: =SUM(D24:D27) -> 3633900 | E23: =SUM(E24:E27) -> 3178310 | F23: =SUM(E23/D23) -> 0.87462781
B24: ILOCOS NORTE | C24: =SUM(mun_coc!C163) -> 706 | D24: =SUM(mun_coc!D163) -> 436087 | E24: =SUM(mun_coc!E163) -> 387957 | F24: =SUM(E24/D24) -> 0.88963211
B25: ILOCOS SUR | C25: =SUM(mun_coc!C189) -> 922 | D25: =SUM(mun_coc!D189) -> 487233 | E25: =SUM(mun_coc!E189) -> 432555 | F25: =SUM(E25/D25) -> 0.88777854
B26: LA UNION | C26: =SUM(mun_coc!C226) -> 840 | D26: =SUM(mun_coc!D226) -> 554274 | E26: =SUM(mun_coc!E226) -> 487073 | F26: =SUM(E26/D26) -> 0.87875852
B27: PANGASINAN | C27: =SUM(mun_coc!C249) -> 2869 | D27: =SUM(mun_coc!D249) -> 2156306 | E27: =SUM(mun_coc!E249) -> 1870725 | F27: =SUM(E27/D27) -> 0.86756008
A28: REGION II | C28: =SUM(C29:C33) -> 3559 | D28: =SUM(D29:D33) -> 2358587 | E28: =SUM(E29:E33) -> 2000940 | F28: =SUM(E28/D28) -> 0.84836387
B29: BATANES | C29: =SUM(mun_coc!C305) -> 33 | D29: =SUM(mun_coc!D305) -> 13655 | E29: =SUM(mun_coc!E305) -> 11488 | F29: =SUM(E29/D29) -> 0.84130355
B30: CAGAYAN | C30: =SUM(mun_coc!C315) -> 1201 | D30: =SUM(mun_coc!D315) -> 785994 | E30: =SUM(mun_coc!E315) -> 674064 | F30: =SUM(E30/D30) -> 0.85759433
B31: ISABELA | C31: =SUM(mun_coc!C348) -> 1671 | D31: =SUM(mun_coc!D348) -> 1125541 | E31: =SUM(mun_coc!E348) -> 944829 | F31: =SUM(E31/D31) -> 0.83944432
B32: NUEVA VIZCAYA | C32: =SUM(mun_coc!C392) -> 452 | D32: =SUM(mun_coc!D392) -> 303090 | E32: =SUM(mun_coc!E392) -> 258249 | F32: =SUM(E32/D32) -> 0.85205385
B33: QUIRINO | C33: =SUM(mun_coc!C411) -> 202 | D33: =SUM(mun_coc!D411) -> 130307 | E33: =SUM(mun_coc!E411) -> 112310 | F33: =SUM(E33/D33) -> 0.8618877
A34: REGION III | C34: =SUM(C35:C41) -> 9584 | D34: =SUM(D35:D41) -> 7699404 | E34: =SUM(E35:E41) -> 6527627 | F34: =SUM(E34/D34) -> 0.84780939
B35: AURORA | C35: =SUM(mun_coc!C422) -> 231 | D35: =SUM(mun_coc!D422) -> 157240 | E35: =SUM(mun_coc!E422) -> 128993 | F35: =SUM(E35/D35) -> 0.82035742
B36: BATAAN | C36: =SUM(mun_coc!C434) -> 739 | D36: =SUM(mun_coc!D434) -> 586044 | E36: =SUM(mun_coc!E434) -> 495413 | F36: =SUM(E36/D36) -> 0.8453512
B37: BULACAN | C37: =SUM(mun_coc!C450) -> 2551 | D37: =SUM(mun_coc!D450) -> 2173026 | E37: =SUM(mun_coc!E450) -> 1847816 | F37: =SUM(E37/D37) -> 0.85034233
B38: NUEVA ECIJA | C38: =SUM(mun_coc!C482) -> 2080 | D38: =SUM(mun_coc!D482) -> 1620166 | E38: =SUM(mun_coc!E482) -> 1349950 | F38: =SUM(E38/D38) -> 0.83321709
B39: PAMPANGA | C39: =SUM(mun_coc!C519) -> 2066 | D39: =SUM(mun_coc!D519) -> 1674789 | E39: =SUM(mun_coc!E519) -> 1418533 | F39: =SUM(E39/D39) -> 0.84699207
B40: TARLAC | C40: =SUM(mun_coc!C546) -> 1220 | D40: =SUM(mun_coc!D546) -> 936003 | E40: =SUM(mun_coc!E546) -> 827669 | F40: =SUM(E40/D40) -> 0.88425892
B41: ZAMBALES | C41: =SUM(mun_coc!C568) -> 697 | D41: =SUM(mun_coc!D568) -> 552136 | E41: =SUM(mun_coc!E568) -> 459253 | F41: =SUM(E41/D41) -> 0.83177514
A42: REGION IV-A | C42: =SUM(C43:C47) -> 12346 | D42: =SUM(D43:D47) -> 9714079 | E42: =SUM(E43:E47) -> 7849709 | F42: =SUM(E42/D42) -> 0.80807547
B43: BATANGAS | C43: =SUM(mun_coc!C586) -> 2569 | D43: =SUM(mun_coc!D586) -> 1958794 | E43: =SUM(mun_coc!E586) -> 1697672 | F43: =SUM(E43/D43) -> 0.86669246
B44: CAVITE | C44: =SUM(mun_coc!C627) -> 2991 | D44: =SUM(mun_coc!D627) -> 2447362 | E44: =SUM(mun_coc!E627) -> 1923752 | F44: =SUM(E44/D44) -> 0.78605127
B45: LAGUNA | C45: =SUM(mun_coc!C659) -> 2626 | D45: =SUM(mun_coc!D659) -> 2140124 | E45: =SUM(mun_coc!E659) -> 1700629 | F45: =SUM(E45/D45) -> 0.7946404
B46: QUEZON | C46: =SUM(mun_coc!C697) -> 2207 | D46: =SUM(mun_coc!D697) -> 1496156 | E46: =SUM(mun_coc!E697) -> 1252204 | F46: =SUM(E46/D46) -> 0.83694748
...

Sheet mun_coc
A1: Republic of the Philippines
A2: COMMISSION ON ELECTIONS
A3: Records and Statistics Division, ERSD
A5: NUMBER AND TURN-OUT OF REGISTERED VOTERS AND VOTERS WHO ACTUALLY VOTED BY CITY/MUNICIPALITY
A6: May 12, 2025 National and Local Elections
A9: As of August 2025
A10: REGION/PROVINCE/CITY/ MUNICIPALITY/LEGISLATIVE/ PROVINCIAL DISTRICT | C10: NUMBER OF CLUSTERED PRECINCTS | D10: NUMBER OF REGISTERED VOTERS | E10: NUMBER OF VOTERS WHO ACTUALLY VOTED | F10: VOTER'S TURNOUT
A13: P H I L I P P I N E S | C13: =SUM(C14+C59+C162+C304+C421+C585+C765+C858+C997+C1120+C1200+C1319+C1486+C1593+C1709+C1783+C1849+C1941) -> 93287 | D13: =SUM(D14+D59+D162+D304+D421+D585+D765+D858+D997+D1120+D1200+D1319+D1486+D1593+D1709+D1783+D1849+D1941) -> 68431965 | E13: =SUM(E14+E59+E162+E304+E421+E585+E765+E858+E997+E1120+E1200+E1319+E1486+E1593+E1709+E1783+E1849+E1941) -> 57070411 | F13: =SUM(E13/D13) -> 0.833973
A14: N. C. R. | C14: =C15+C22+C29+C33+C36+C39+C42+C45+C48+C51+C52+C53+C54+C55+C56+C57+C58 -> 9030 | D14: =D15+D22+D29+D33+D36+D39+D42+D45+D48+D51+D52+D53+D54+D55+D56+D57+D58 -> 7563520 | E14: =E15+E22+E29+E33+E36+E39+E42+E45+E48+E51+E52+E53+E54+E55+E56+E57+E58 -> 6040069 | F14: =SUM(E14/D14) -> 0.7985791
A15: City of Manila | C15: =SUM(C16:C21) -> 1585 | D15: =SUM(D16:D21) -> 1142174 | E15: =SUM(E16:E21) -> 929012 | F15: =SUM(E15/D15) -> 0.81337169
B16: 1st Legislative District | C16: 346 | D16: 267797 | E16: 224005 | F16: =SUM(E16/D16) -> 0.83647315
B17: 2nd Legislative District | C17: 213 | D17: 149095 | E17: 122409 | F17: =SUM(E17/D17) -> 0.82101345
B18: 3rd Legislative District | C18: 217 | D18: 156053 | E18: 123045 | F18: =SUM(E18/D18) -> 0.78848212
B19: 4th Legislative District | C19: 252 | D19: 172679 | E19: 139619 | F19: =SUM(E19/D19) -> 0.80854649
B20: 5th Legislative District | C20: 315 | D20: 227051 | E20: 181596 | F20: =SUM(E20/D20) -> 0.79980269
B21: 6th Legislative District | C21: 242 | D21: 169499 | E21: 138338 | F21: =SUM(E21/D21) -> 0.81615821
A22: Quezon City | C22: =SUM(C23:C28) -> 1658 | D22: =SUM(D23:D28) -> 1454411 | E22: =SUM(E23:E28) -> 1150586 | F22: =SUM(E22/D22) -> 0.791101
B23: 1st Legislative District | C23: 247 | D23: 217676 | E23: 168049 | F23: =SUM(E23/D23) -> 0.77201437
B24: 2nd Legislative District | C24: 372 | D24: 328316 | E24: 257836 | F24: =SUM(E24/D24) -> 0.78532877
B25: 3rd Legislative District | C25: 204 | D25: 172497 | E25: 139339 | F25: =SUM(E25/D25) -> 0.80777637
B26: 4th Legislative District | C26: 268 | D26: 234450 | E26: 193458 | F26: =SUM(E26/D26) -> 0.82515675
B27: 5th Legislative District | C27: 313 | D27: 281197 | E27: 221705 | F27: =SUM(E27/D27) -> 0.78843302
B28: 6th Legislative District | C28: 254 | D28: 220275 | E28: 170199 | F28: =SUM(E28/D28) -> 0.77266599
A29: City of Caloocan | C29: =SUM(C30:C32) -> 905 | D29: =SUM(D30:D32) -> 765249 | E29: =SUM(E30:E32) -> 606213 | F29: =SUM(E29/D29) -> 0.79217745
B30: 1st Legislative District | C30: 432 | D30: 377294 | E30: 297493 | F30: =SUM(E30/D30) -> 0.7884912
B31: 2nd Legislative District | C31: 300 | D31: 237712 | E31: 188617 | F31: =SUM(E31/D31) -> 0.79346857
B32: 3rd Legislative District | C32: 173 | D32: 150243 | E32: 120103 | F32: =SUM(E32/D32) -> 0.79939165
A33: City of Makati | C33: =SUM(C34:C35) -> 300 | D33: =SUM(D34:D35) -> 270240 | E33: =SUM(E34:E35) -> 210052 | F33: =SUM(E33/D33) -> 0.77727946
B34: 1st Legislative District | C34: 240 | D34: 216152 | E34: 170882 | F34: =SUM(E34/D34) -> 0.79056405
B35: 2nd Legislative District | C35: 60 | D35: 54088 | E35: 39170 | F35: =SUM(E35/D35) -> 0.72419021
A36: City of Marikina | C36: =SUM(C37:C38) -> 363 | D36: =SUM(D37:D38) -> 315980 | E36: =SUM(E37:E38) -> 258466 | F36: =SUM(E36/D36) -> 0.81798215
B37: 1st Legislative District | C37: 148 | D37: 127290 | E37: 107054 | F37: =SUM(E37/D37) -> 0.84102443
B38: 2nd Legislative District | C38: 215 | D38: 188690 | E38: 151412 | F38: =SUM(E38/D38) -> 0.80243786
A39: City of Parañaque | C39: =SUM(C40:C41) -> 402 | D39: =SUM(D40:D41) -> 353274 | E39: =SUM(E40:E41) -> 278341 | F39: =SUM(E39/D39) -> 0.78788985
B40: 1st Legislative District | C40: 156 | D40: 139653 | E40: 105462 | F40: =SUM(E40/D40) -> 0.75517175
B41: 2nd Legislative District | C41: 246 | D41: 213621 | E41: 172879 | F41: =SUM(E41/D41) -> 0.80927905
A42: City of Pasig | C42: =SUM(C43:C44) -> 519 | D42: =SUM(D43:D44) -> 463885 | E42: =SUM(E43:E44) -> 386057 | F42: =SUM(E42/D42) -> 0.83222566
B43: 1st Councilor District | C43: 210 | D43: 181637 | E43: 150207 | F43: =SUM(E43/D43) -> 0.82696257
B44: 2nd Councilor District | C44: 309 | D44: 282248 | E44: 235850 | F44: =SUM(E44/D44) -> 0.83561265
A45: City of Valenzuela | C45: =SUM(C46:C47) -> 511 | D45: =SUM(D46:D47) -> 438556 | E45: =SUM(E46:E47) -> 353937 | F45: =SUM(E45/D45) -> 0.80705087
...

Sheet OVERSEAS VOTING
A1: Republic of the Philippines
A2: COMMISSION ON ELECTIONS
A3: Records and Statistics Division, ERSD
A4: NUMBER AND TURN-OUT OF REGISTERED VOTERS FOR OVERSEAS VOTING, PER COUNTRY
A5: May 12, 2025 National and Local Elections
A7: As of August 2025
A8: COUNTRY | C8: BASED ON CERTIFICATE OF CANVASS
C10: NUMBER OF REGISTERED VOTERS | D10: NUMBER OF VOTERS WHO ACTUALLY VOTED | E10: VOTER'S TURN-OUT
A11: OVERSEAS AUTOMATED VOTING | C11: =C12+C34+C41+C59 -> 1241688 | D11: =D12+D34+D41+D59 -> 228490 | E11: =SUM(D11/C11) -> 0.18401563
A12: ASIA PACIFIC | C12: =SUM(C13:C33) -> 383392 | D12: =SUM(D13:D33) -> 92616 | E12: =SUM(D12/C12) -> 0.24156999
B13: THAILAND | C13: 8203 | D13: 2609 | E13: =SUM(D13/C13) -> 0.31805437
B14: CHINA | C14: 3809 | D14: 1082 | E14: =SUM(D14/C14) -> 0.28406406
B15: BRUNEI | C15: 6167 | D15: 1692 | E15: =SUM(D15/C15) -> 0.27436355
B16: AUSTRALIA | C16: 19466 | D16: 3206 | E16: =SUM(D16/C16) -> 0.16469742
B17: BANGLADESH | C17: 911 | D17: 249 | E17: =SUM(D17/C17) -> 0.27332602
B18: TIMOR-LESTE | C18: 554 | D18: 277 | E18: =SUM(D18/C18) -> 0.5
B19: VIETNAM | C19: 1875 | D19: 476 | E19: =SUM(D19/C19) -> 0.25386667
B20: CHINA | C20: 94295 | D20: 31637 | E20: =SUM(D20/C20) -> 0.3355109
B21: PAKISTAN | C21: 607 | D21: 216 | E21: =SUM(D21/C21) -> 0.35584843
B22: INDONESIA | C22: 2645 | D22: 792 | E22: =SUM(D22/C22) -> 0.29943289
B23: MALAYSIA | C23: 9669 | D23: 2747 | E23: =SUM(D23/C23) -> 0.28410384
B24: TAIWAN, ROC | C24: 71009 | D24: 12978 | E24: =SUM(D24/C24) -> 0.18276556
... B33: MYANMAR | C33: 370 | D33: 144 | E33: =SUM(D33/C33) -> 0.38918919
A34: NORTH AND LATIN AMERICA | C34: =SUM(C35:C40) -> 259415 | D34: =SUM(D35:D40) -> 18640 | E34: =SUM(D34/C34) -> 0.071853979
B35: BRAZIL | C35: 1088 | D35: 231 | E35: =SUM(D35/C35) -> 0.21231618
B36: ARGENTINA | C36: 208 | D36: 78 | E36: =SUM(D36/C36) -> 0.375
B37: MEXICO | C37: 844 | D37: 235 | E37: =SUM(D37/C37) -> 0.27843602
B38: CANADA | C38: 67873 | D38: 7912 | E38: =SUM(D38/C38) -> 0.11657065
B39: CHILE | C39: 883 | D39: 378 | E39: =SUM(D39/C39) -> 0.42808607
B40: UNITED STATES OF AMERICA | C40: 188519 | D40: 9806 | E40: =SUM(D40/C40) -> 0.052015977
A41: MIDDLE EAST AND AFRICAS | C41: =SUM(C42:C58) -> 453500 | D41: =SUM(D42:D58) -> 88537 | E41: =SUM(D41/C41) -> 0.19523043
B42: UNITED ARAB EMIRATES | C42: 189892 | D42: 37976 | E42: =SUM(D42/C42) -> 0.19998736
B43: NIGERIA | C43: 1021 | D43: 367 | E43: =SUM(D43/C43) -> 0.35945152
B44: JORDAN | C44: 4003 | D44: 860 | E44: =SUM(D44/C44) -> 0.21483887
B45: LEBANON | C45: 6103 | D45: 1918 | E45: =SUM(D45/C45) -> 0.31427167
B46: EGYPT | C46: 1931 | D46: 314 | E46: =SUM(D46/C46) -> 0.16261005
B47: SYRIA | C47: 95 | D47: 40 | E47: =SUM(D47/C47) -> 0.42105263
B48: QUATAR | C48: 31922 | D48: 10418 | E48: =SUM(D48/C48) -> 0.326358
B49: KUWAIT | C49: 36046 | D49: 7323 | E49: =SUM(D49/C49) -> 0.20315708
B50: BAHRAIN | C50: 22451 | D50: 4554 | E50: =SUM(D50/C50) -> 0.20284174
...
